<?xml version="1.0" encoding="UTF-8"?>
<!-- Generated by org.testng.reporters.JUnitReportReporter -->
<testsuite skipped="0" hostname="Chan" name="com.crm.SDET26.Opportunity.ClickOnSaveAndAllTheFillSareSaveOrNot" tests="1" failures="1" timestamp="10 Dec 2021 15:46:28 GMT" time="23.313" errors="0">
  <testcase name="cickOnSaveAndAllTheFillSareSaveOrNot" time="23.313" classname="com.crm.SDET26.Opportunity.ClickOnSaveAndAllTheFillSareSaveOrNot">
    <failure type="java.lang.AssertionError" message="expected [true] but found [false]">
      <![CDATA[java.lang.AssertionError: expected [true] but found [false]
at org.testng.Assert.fail(Assert.java:96)
at org.testng.Assert.failNotEquals(Assert.java:776)
at org.testng.Assert.assertTrue(Assert.java:44)
at org.testng.Assert.assertTrue(Assert.java:54)
at com.crm.SDET26.Opportunity.ClickOnSaveAndAllTheFillSareSaveOrNot.cickOnSaveAndAllTheFillSareSaveOrNot(ClickOnSaveAndAllTheFillSareSaveOrNot.java:71)
at sun.reflect.NativeMethodAccessorImpl.invoke0(Native Method)
at sun.reflect.NativeMethodAccessorImpl.invoke(Unknown Source)
at sun.reflect.DelegatingMethodAccessorImpl.invoke(Unknown Source)
at java.lang.reflect.Method.invoke(Unknown Source)
at org.testng.internal.MethodInvocationHelper.invokeMethod(MethodInvocationHelper.java:124)
at org.testng.internal.Invoker.invokeMethod(Invoker.java:583)
at org.testng.internal.Invoker.invokeTestMethod(Invoker.java:719)
at org.testng.internal.Invoker.invokeTestMethods(Invoker.java:989)
at org.testng.internal.TestMethodWorker.invokeTestMethods(TestMethodWorker.java:125)
at org.testng.internal.TestMethodWorker.run(TestMethodWorker.java:109)
at java.util.concurrent.ThreadPoolExecutor.runWorker(Unknown Source)
at java.util.concurrent.ThreadPoolExecutor$Worker.run(Unknown Source)
at java.lang.Thread.run(Unknown Source)
]]>
    </failure>
  </testcase> <!-- cickOnSaveAndAllTheFillSareSaveOrNot -->
</testsuite> <!-- com.crm.SDET26.Opportunity.ClickOnSaveAndAllTheFillSareSaveOrNot -->
